Workbook
Name AppointmentDate: cálculos!$P$2
Name CalendarGrid: 'Planner anual'!$C$6:$N$42
Name Calendario: cálculos!$C$6:$N$43
Name Citas: IF(LEN(cálculos!$C$7:$N$43),COUNTIFS(Citas!$B$5:$B$18,cálculos!$C$7:$N$43,Citas!$B$5:$B$18,">0"),0)
Name DateCriteria: cálculos!$P$1:$P$2
Name DayGlance: 'Planner anual'!$Q$3:$Q$5
Name DayHeader_Values: ROW(cálculos!$1:$32)
Name DayHeaders: 'Planner anual'!$B$6:$B$36
Name MonthHeader_Values: EOMONTH(DATE('Planner anual'!StartYear,8,1),{0,1,2,3,4,5,6,7,8,9,10,11})+1
Name MonthHeaders: 'Planner anual'!$C$5:$N$5
Name MonthNumbers: {9,10,11,12,1,2,3,4,5,6,7,8}
Name StartYear: 'Planner anual'!$C$3
Name TodaysDate: 'Planner anual'!$Q$5

Sheet Planner anual
B1: =StartYear&" - "&StartYear+1 -> 2020 - 2021 | F1: CALENDARIO DEL AÑO DE LA UNIVERSIDAD
C3: =YEAR(TODAY()) -> 2020 | D3: Año de inicio | Q3: VISTA DE HOY
C5: {=MonthHeader_Values} -> 44075 | D5: 44105 | E5: 44136 | F5: 44166 | G5: 44197 | H5: 44228 | I5: 44256 | J5: 44287 | K5: 44317 | L5: 44348 | M5: 44378 | N5: 44409 | Q5: =TODAY() -> 43944
B6: {=cálculos!B7:B43} -> LUN | C6: {=Citas} -> 0 | D6: 0 | E6: 0 | F6: 0 | G6: 0 | H6: 0 | I6: 0 | J6: 0 | K6: 0 | L6: 0 | M6: 0 | N6: 0 | P6: {=IFERROR(VLOOKUP(1,TodaysApptsSorted[],2,FALSE),"")} -> 0.41666667 | Q6: {=IFERROR(VLOOKUP(1,TodaysApptsSorted[],3,FALSE),"")} -> Dentista
B7: MAR | C7: 0 | D7: 0 | E7: 0 | F7: 0 | G7: 0 | H7: 0 | I7: 0 | J7: 0 | K7: 0 | L7: 0 | M7: 0 | N7: 0 | P7: {=IFERROR(VLOOKUP(2,TodaysApptsSorted[],2,FALSE),"")} -> 0.875 | Q7: {=IFERROR(VLOOKUP(2,TodaysApptsSorted[],3,FALSE),"")} -> Fiesta de cumpleaños de Ana
B8: MIÉ | C8: 0 | D8: 0 | E8: 0 | F8: 0 | G8: 0 | H8: 0 | I8: 0 | J8: 0 | K8: 0 | L8: 0 | M8: 0 | N8: 0 | P8: {=IFERROR(VLOOKUP(3,TodaysApptsSorted[],2,FALSE),"")} | Q8: {=IFERROR(VLOOKUP(3,TodaysApptsSorted[],3,FALSE),"")}
B9: JUE | C9: 0 | D9: 0 | E9: 0 | F9: 0 | G9: 0 | H9: 0 | I9: 0 | J9: 0 | K9: 0 | L9: 0 | M9: 0 | N9: 0 | P9: {=IFERROR(VLOOKUP(4,TodaysApptsSorted[],2,FALSE),"")} | Q9: {=IFERROR(VLOOKUP(4,TodaysApptsSorted[],3,FALSE),"")}
B10: VIE | C10: 0 | D10: 0 | E10: 0 | F10: 0 | G10: 0 | H10: 0 | I10: 0 | J10: 0 | K10: 0 | L10: 0 | M10: 0 | N10: 0 | P10: {=IFERROR(VLOOKUP(5,TodaysApptsSorted[],2,FALSE),"")} | Q10: {=IFERROR(VLOOKUP(5,TodaysApptsSorted[],3,FALSE),"")}
B11: SÁB | C11: 0 | D11: 0 | E11: 0 | F11: 0 | G11: 0 | H11: 0 | I11: 0 | J11: 0 | K11: 0 | L11: 0 | M11: 0 | N11: 0 | P11: {=IFERROR(VLOOKUP(6,TodaysApptsSorted[],2,FALSE),"")} | Q11: {=IFERROR(VLOOKUP(6,TodaysApptsSorted[],3,FALSE),"")}
B12: DOM | C12: 0 | D12: 0 | E12: 0 | F12: 0 | G12: 0 | H12: 0 | I12: 0 | J12: 0 | K12: 0 | L12: 0 | M12: 0 | N12: 0 | P12: {=IFERROR(VLOOKUP(7,TodaysApptsSorted[],2,FALSE),"")} | Q12: {=IFERROR(VLOOKUP(7,TodaysApptsSorted[],3,FALSE),"")}
B13: LUN. | C13: 0 | D13: 0 | E13: 0 | F13: 0 | G13: 0 | H13: 0 | I13: 0 | J13: 0 | K13: 0 | L13: 0 | M13: 0 | N13: 0 | P13: {=IFERROR(VLOOKUP(8,TodaysApptsSorted[],2,FALSE),"")} | Q13: {=IFERROR(VLOOKUP(8,TodaysApptsSorted[],3,FALSE),"")}
B14: MAR | C14: 0 | D14: 0 | E14: 0 | F14: 0 | G14: 0 | H14: 0 | I14: 0 | J14: 0 | K14: 0 | L14: 0 | M14: 0 | N14: 0 | P14: {=IFERROR(VLOOKUP(9,TodaysApptsSorted[],2,FALSE),"")} | Q14: {=IFERROR(VLOOKUP(9,TodaysApptsSorted[],3,FALSE),"")}
B15: MIÉ | C15: 0 | D15: 0 | E15: 0 | F15: 0 | G15: 0 | H15: 0 | I15: 0 | J15: 0 | K15: 0 | L15: 0 | M15: 0 | N15: 0 | P15: {=IFERROR(VLOOKUP(10,TodaysApptsSorted[],2,FALSE),"")} | Q15: {=IFERROR(VLOOKUP(10,TodaysApptsSorted[],3,FALSE),"")}
B16: JUE | C16: 0 | D16: 0 | E16: 0 | F16: 0 | G16: 0 | H16: 0 | I16: 0 | J16: 0 | K16: 0 | L16: 0 | M16: 0 | N16: 0 | P16: {=IFERROR(VLOOKUP(11,TodaysApptsSorted[],2,FALSE),"")} | Q16: {=IFERROR(VLOOKUP(11,TodaysApptsSorted[],3,FALSE),"")}
B17: VIE | C17: 0 | D17: 0 | E17: 0 | F17: 0 | G17: 0 | H17: 0 | I17: 0 | J17: 0 | K17: 0 | L17: 0 | M17: 0 | N17: 0 | P17: {=IFERROR(VLOOKUP(12,TodaysApptsSorted[],2,FALSE),"")} | Q17: {=IFERROR(VLOOKUP(12,TodaysApptsSorted[],3,FALSE),"")}
B18: SÁB | C18: 0 | D18: 0 | E18: 0 | F18: 0 | G18: 0 | H18: 0 | I18: 0 | J18: 0 | K18: 0 | L18: 0 | M18: 0 | N18: 0 | P18: {=IFERROR(VLOOKUP(13,TodaysApptsSorted[],2,FALSE),"")} | Q18: {=IFERROR(VLOOKUP(13,TodaysApptsSorted[],3,FALSE),"")}
B19: DOM | C19: 0 | D19: 0 | E19: 0 | F19: 0 | G19: 0 | H19: 0 | I19: 0 | J19: 0 | K19: 0 | L19: 0 | M19: 0 | N19: 0 | P19: {=IFERROR(VLOOKUP(14,TodaysApptsSorted[],2,FALSE),"")} | Q19: {=IFERROR(VLOOKUP(14,TodaysApptsSorted[],3,FALSE),"")}
B20: LUN. | C20: 0 | D20: 0 | E20: 0 | F20: 0 | G20: 0 | H20: 0 | I20: 0 | J20: 0 | K20: 0 | L20: 0 | M20: 0 | N20: 0 | P20: {=IFERROR(VLOOKUP(15,TodaysApptsSorted[],2,FALSE),"")} | Q20: {=IFERROR(VLOOKUP(15,TodaysApptsSorted[],3,FALSE),"")}
B21: MAR | C21: 0 | D21: 0 | E21: 0 | F21: 0 | G21: 0 | H21: 0 | I21: 0 | J21: 0 | K21: 0 | L21: 0 | M21: 0 | N21: 0 | P21: {=IFERROR(VLOOKUP(16,TodaysApptsSorted[],2,FALSE),"")} | Q21: {=IFERROR(VLOOKUP(16,TodaysApptsSorted[],3,FALSE),"")}
B22: MIÉ | C22: 0 | D22: 0 | E22: 0 | F22: 0 | G22: 0 | H22: 0 | I22: 0 | J22: 0 | K22: 0 | L22: 0 | M22: 0 | N22: 0 | P22: {=IFERROR(VLOOKUP(17,TodaysApptsSorted[],2,FALSE),"")} | Q22: {=IFERROR(VLOOKUP(17,TodaysApptsSorted[],3,FALSE),"")}
B23: JUE | C23: 0 | D23: 0 | E23: 0 | F23: 0 | G23: 0 | H23: 0 | I23: 0 | J23: 0 | K23: 0 | L23: 0 | M23: 0 | N23: 0 | P23: {=IFERROR(VLOOKUP(18,TodaysApptsSorted[],2,FALSE),"")} | Q23: {=IFERROR(VLOOKUP(18,TodaysApptsSorted[],3,FALSE),"")}
B24: VIE | C24: 0 | D24: 0 | E24: 0 | F24: 0 | G24: 0 | H24: 0 | I24: 0 | J24: 0 | K24: 0 | L24: 0 | M24: 0 | N24: 0 | P24: {=IFERROR(VLOOKUP(19,TodaysApptsSorted[],2,FALSE),"")} | Q24: {=IFERROR(VLOOKUP(19,TodaysApptsSorted[],3,FALSE),"")}
B25: SÁB | C25: 0 | D25: 0 | E25: 0 | F25: 0 | G25: 0 | H25: 0 | I25: 0 | J25: 0 | K25: 0 | L25: 0 | M25: 0 | N25: 0 | P25: {=IFERROR(VLOOKUP(20,TodaysApptsSorted[],2,FALSE),"")} | Q25: {=IFERROR(VLOOKUP(20,TodaysApptsSorted[],3,FALSE),"")}
B26: DOM | C26: 0 | D26: 0 | E26: 0 | F26: 0 | G26: 0 | H26: 0 | I26: 0 | J26: 0 | K26: 0 | L26: 0 | M26: 0 | N26: 0
B27: LUN. | C27: 0 | D27: 0 | E27: 0 | F27: 0 | G27: 0 | H27: 0 | I27: 0 | J27: 0 | K27: 0 | L27: 0 | M27: 0 | N27: 0
B28: MAR | C28: 0 | D28: 0 | E28: 0 | F28: 0 | G28: 0 | H28: 0 | I28: 0 | J28: 0 | K28: 0 | L28: 0 | M28: 0 | N28: 0
B29: MIÉ | C29: 0 | D29: 0 | E29: 0 | F29: 0 | G29: 0 | H29: 0 | I29: 0 | J29: 0 | K29: 0 | L29: 0 | M29: 0 | N29: 0
B30: JUE | C30: 0 | D30: 0 | E30: 0 | F30: 0 | G30: 0 | H30: 0 | I30: 0 | J30: 0 | K30: 0 | L30: 0 | M30: 0 | N30: 0
B31: VIE | C31: 0 | D31: 0 | E31: 0 | F31: 0 | G31: 0 | H31: 0 | I31: 0 | J31: 0 | K31: 0 | L31: 0 | M31: 0 | N31: 0
B32: SÁB | C32: 0 | D32: 0 | E32: 0 | F32: 0 | G32: 0 | H32: 0 | I32: 0 | J32: 0 | K32: 0 | L32: 0 | M32: 0 | N32: 0
B33: DOM | C33: 0 | D33: 0 | E33: 0 | F33: 0 | G33: 0 | H33: 0 | I33: 0 | J33: 0 | K33: 0 | L33: 0 | M33: 0 | N33: 0
B34: LUN. | C34: 0 | D34: 0 | E34: 0 | F34: 0 | G34: 0 | H34: 0 | I34: 0 | J34: 0 | K34: 0 | L34: 0 | M34: 0 | N34: 0
B35: MAR | C35: 0 | D35: 0 | E35: 0 | F35: 0 | G35: 0 | H35: 0 | I35: 0 | J35: 0 | K35: 0 | L35: 0 | M35: 0 | N35: 0
B36: MIÉ | C36: 0 | D36: 0 | E36: 0 | F36: 0 | G36: 0 | H36: 0 | I36: 0 | J36: 0 | K36: 0 | L36: 0 | M36: 0 | N36: 0
B37: JUE | C37: 0 | D37: 0 | E37: 0 | F37: 0 | G37: 0 | H37: 0 | I37: 0 | J37: 0 | K37: 0 | L37: 0 | M37: 0 | N37: 0
... B42: MAR | C42: 0 | D42: 0 | E42: 0 | F42: 0 | G42: 0 | H42: 0 | I42: 0 | J42: 0 | K42: 0 | L42: 0 | M42: 0 | N42: 0

Sheet Citas
B1: CITAS
B3: CITAS
B4: FECHA | C4: HORA | D4: DESCRIPCIÓN
B5: =TODAY() -> 43944 | C5: 0.41666667 | D5: Dentista
B6: =TODAY() -> 43944 | C6: 0.875 | D6: Fiesta de cumpleaños de Ana
B7: =TODAY()+1 -> 43945 | C7: 0.66666667 | D7: Grupo de estudio
B8: =TODAY()+2 -> 43946 | C8: 0.875 | D8: Repartir folletos en el Centro juvenil
B9: =TODAY()+3 -> 43947 | C9: 0.41666667 | D9: Grupo de estudio
B10: =TODAY()+4 -> 43948 | C10: 0.54166667 | D10: Parcial
B11: =TODAY()+5 -> 43949 | C11: 0.625 | D11: Parcial
B12: =TODAY()+7 -> 43951 | C12: 0.75 | D12: Fiesta del campus
B13: =TODAY()+8 -> 43952 | C13: 0.4375 | D13: Quedar con Alberto en el gimnasio
B14: =TODAY()+9 -> 43953 | C14: 0.41666667 | D14: Parcial
B15: =TODAY()+10 -> 43954 | C15: 0.79166667 | D15: Grupo de estudio
B16: =TODAY()+11 -> 43955 | C16: 0.875 | D16: Carrera nocturna

Sheet cálculos
P1: Fecha
C2: Cálculos ocultos | P2: =TODAY() -> 43944 | S2: Clasificación de ordenación automática de tareas diarias, los elementos idénticos están en el mismo día
S3: funciona con hasta 20 citas en un mismo día
C4: *** Esta hoja debe permanecer oculta *** | R4: Salto de tiempo | S4: RANGO | T4: Hora | U4: Cita | W4: Jerarquía ordenada | X4: Hora | Y4: Cita
R5: =IFERROR(RANK(S5,cálculos!$S$5:$S$24,1)+SUMPRODUCT(--(S5=cálculos!$S$5:$S$24),--(U5>cálculos!$U$5:$U$24)),"") -> 1 | S5: =IFERROR(RANK($T5,cálculos!$T$5:$T$24,1),"") -> 1 | T5: {=IFERROR(INDEX(AppointmentDetails[],SMALL(IF(AppointmentDetails[FECHA]=TodaysDate,ROW(AppointmentDetails[FECHA])-4),ROW(A1)),2),"")} -> 0.41666667 | U5: {=IFERROR(INDEX(AppointmentDetails[],SMALL(IF(AppointmentDetails[FECHA]=TodaysDate,ROW(AppointmentDetails[FECHA])-4),ROW(A1)),3),"")} -> Dentista | W5: 1 | X5: =IFERROR(VLOOKUP(W5,SortTable[],3,FALSE),"") -> 0.41666667 | Y5: =IFERROR(VLOOKUP(W5,SortTable[],4,FALSE),"") -> Dentista
C6: {=MonthHeader_Values} -> 44075 | D6: 44105 | E6: 44136 | F6: 44166 | G6: 44197 | H6: 44228 | I6: 44256 | J6: 44287 | K6: 44317 | L6: 44348 | M6: 44378 | N6: 44409 | R6: =IFERROR(RANK(S6,cálculos!$S$5:$S$24,1)+SUMPRODUCT(--(S6=cálculos!$S$5:$S$24),--(U6>cálculos!$U$5:$U$24)),"") -> 2 | S6: =IFERROR(RANK($T6,cálculos!$T$5:$T$24,1),"") -> 2 | T6: {=IFERROR(INDEX(AppointmentDetails[],SMALL(IF(AppointmentDetails[FECHA]=TodaysDate,ROW(AppointmentDetails[FECHA])-4),ROW(A2)),2),"")} -> 0.875 | U6: {=IFERROR(INDEX(AppointmentDetails[],SMALL(IF(AppointmentDetails[FECHA]=TodaysDate,ROW(AppointmentDetails[FECHA])-4),ROW(A2)),3),"")} -> Fiesta de cumpleaños de Ana | W6: 2 | X6: =IFERROR(VLOOKUP(W6,SortTable[],3,FALSE),"") -> 0.875 | Y6: =IFERROR(VLOOKUP(W6,SortTable[],4,FALSE),"") -> Fiesta de cumpleaños de Ana
B7: LUN | C7: {=IF(MONTH(C6:N6-WEEKDAY(C6:N6,2)+ROW(1:50))=MONTH(C6:N6),C6:N6-WEEKDAY(C6:N6,2)+ROW(1:50),"")} | H7: 44228 | I7: 44256 | R7: =IFERROR(RANK(S7,cálculos!$S$5:$S$24,1)+SUMPRODUCT(--(S7=cálculos!$S$5:$S$24),--(U7>cálculos!$U$5:$U$24)),"") | S7: =IFERROR(RANK($T7,cálculos!$T$5:$T$24,1),"") | T7: {=IFERROR(INDEX(AppointmentDetails[],SMALL(IF(AppointmentDetails[FECHA]=TodaysDate,ROW(AppointmentDetails[FECHA])-4),ROW(A3)),2),"")} | U7: {=IFERROR(INDEX(AppointmentDetails[],SMALL(IF(AppointmentDetails[FECHA]=TodaysDate,ROW(AppointmentDetails[FECHA])-4),ROW(A3)),3),"")} | W7: 3 | X7: =IFERROR(VLOOKUP(W7,SortTable[],3,FALSE),"") | Y7: =IFERROR(VLOOKUP(W7,SortTable[],4,FALSE),"")
B8: MAR | C8: 44075 | F8: 44166 | H8: 44229 | I8: 44257 | L8: 44348 | R8: =IFERROR(RANK(S8,cálculos!$S$5:$S$24,1)+SUMPRODUCT(--(S8=cálculos!$S$5:$S$24),--(U8>cálculos!$U$5:$U$24)),"") | S8: =IFERROR(RANK($T8,cálculos!$T$5:$T$24,1),"") | T8: {=IFERROR(INDEX(AppointmentDetails[],SMALL(IF(AppointmentDetails[FECHA]=TodaysDate,ROW(AppointmentDetails[FECHA])-4),ROW(A4)),2),"")} | U8: {=IFERROR(INDEX(AppointmentDetails[],SMALL(IF(AppointmentDetails[FECHA]=TodaysDate,ROW(AppointmentDetails[FECHA])-4),ROW(A4)),3),"")} | W8: 4 | X8: =IFERROR(VLOOKUP(W8,SortTable[],3,FALSE),"") | Y8: =IFERROR(VLOOKUP(W8,SortTable[],4,FALSE),"")
B9: MIÉ | C9: 44076 | F9: 44167 | H9: 44230 | I9: 44258 | L9: 44349 | R9: =IFERROR(RANK(S9,cálculos!$S$5:$S$24,1)+SUMPRODUCT(--(S9=cálculos!$S$5:$S$24),--(U9>cálculos!$U$5:$U$24)),"") | S9: =IFERROR(RANK($T9,cálculos!$T$5:$T$24,1),"") | T9: {=IFERROR(INDEX(AppointmentDetails[],SMALL(IF(AppointmentDetails[FECHA]=TodaysDate,ROW(AppointmentDetails[FECHA])-4),ROW(A5)),2),"")} | U9: {=IFERROR(INDEX(AppointmentDetails[],SMALL(IF(AppointmentDetails[FECHA]=TodaysDate,ROW(AppointmentDetails[FECHA])-4),ROW(A5)),3),"")} | W9: 5 | X9: =IFERROR(VLOOKUP(W9,SortTable[],3,FALSE),"") | Y9: =IFERROR(VLOOKUP(W9,SortTable[],4,FALSE),"")
B10: JUE | C10: 44077 | D10: 44105 | F10: 44168 | H10: 44231 | I10: 44259 | J10: 44287 | L10: 44350 | M10: 44378 | R10: =IFERROR(RANK(S10,cálculos!$S$5:$S$24,1)+SUMPRODUCT(--(S10=cálculos!$S$5:$S$24),--(U10>cálculos!$U$5:$U$24)),"") | S10: =IFERROR(RANK($T10,cálculos!$T$5:$T$24,1),"") | T10: {=IFERROR(INDEX(AppointmentDetails[],SMALL(IF(AppointmentDetails[FECHA]=TodaysDate,ROW(AppointmentDetails[FECHA])-4),ROW(A6)),2),"")} | U10: {=IFERROR(INDEX(AppointmentDetails[],SMALL(IF(AppointmentDetails[FECHA]=TodaysDate,ROW(AppointmentDetails[FECHA])-4),ROW(A6)),3),"")} | W10: 6 | X10: =IFERROR(VLOOKUP(W10,SortTable[],3,FALSE),"") | Y10: =IFERROR(VLOOKUP(W10,SortTable[],4,FALSE),"")
B11: VIE | C11: 44078 | D11: 44106 | F11: 44169 | G11: 44197 | H11: 44232 | I11: 44260 | J11: 44288 | L11: 44351 | M11: 44379 | R11: =IFERROR(RANK(S11,cálculos!$S$5:$S$24,1)+SUMPRODUCT(--(S11=cálculos!$S$5:$S$24),--(U11>cálculos!$U$5:$U$24)),"") | S11: =IFERROR(RANK($T11,cálculos!$T$5:$T$24,1),"") | T11: {=IFERROR(INDEX(AppointmentDetails[],SMALL(IF(AppointmentDetails[FECHA]=TodaysDate,ROW(AppointmentDetails[FECHA])-4),ROW(A7)),2),"")} | U11: {=IFERROR(INDEX(AppointmentDetails[],SMALL(IF(AppointmentDetails[FECHA]=TodaysDate,ROW(AppointmentDetails[FECHA])-4),ROW(A7)),3),"")} | W11: 7 | X11: =IFERROR(VLOOKUP(W11,SortTable[],3,FALSE),"") | Y11: =IFERROR(VLOOKUP(W11,SortTable[],4,FALSE),"")
B12: SÁB | C12: 44079 | D12: 44107 | F12: 44170 | G12: 44198 | H12: 44233 | I12: 44261 | J12: 44289 | K12: 44317 | L12: 44352 | M12: 44380 | R12: =IFERROR(RANK(S12,cálculos!$S$5:$S$24,1)+SUMPRODUCT(--(S12=cálculos!$S$5:$S$24),--(U12>cálculos!$U$5:$U$24)),"") | S12: =IFERROR(RANK($T12,cálculos!$T$5:$T$24,1),"") | T12: {=IFERROR(INDEX(AppointmentDetails[],SMALL(IF(AppointmentDetails[FECHA]=TodaysDate,ROW(AppointmentDetails[FECHA])-4),ROW(A8)),2),"")} | U12: {=IFERROR(INDEX(AppointmentDetails[],SMALL(IF(AppointmentDetails[FECHA]=TodaysDate,ROW(AppointmentDetails[FECHA])-4),ROW(A8)),3),"")} | W12: 8 | X12: =IFERROR(VLOOKUP(W12,SortTable[],3,FALSE),"") | Y12: =IFERROR(VLOOKUP(W12,SortTable[],4,FALSE),"")
B13: DOM | C13: 44080 | D13: 44108 | E13: 44136 | F13: 44171 | G13: 44199 | H13: 44234 | I13: 44262 | J13: 44290 | K13: 44318 | L13: 44353 | M13: 44381 | N13: 44409 | R13: =IFERROR(RANK(S13,cálculos!$S$5:$S$24,1)+SUMPRODUCT(--(S13=cálculos!$S$5:$S$24),--(U13>cálculos!$U$5:$U$24)),"") | S13: =IFERROR(RANK($T13,cálculos!$T$5:$T$24,1),"") | T13: {=IFERROR(INDEX(AppointmentDetails[],SMALL(IF(AppointmentDetails[FECHA]=TodaysDate,ROW(AppointmentDetails[FECHA])-4),ROW(A9)),2),"")} | U13: {=IFERROR(INDEX(AppointmentDetails[],SMALL(IF(AppointmentDetails[FECHA]=TodaysDate,ROW(AppointmentDetails[FECHA])-4),ROW(A9)),3),"")} | W13: 9 | X13: =IFERROR(VLOOKUP(W13,SortTable[],3,FALSE),"") | Y13: =IFERROR(VLOOKUP(W13,SortTable[],4,FALSE),"")
B14: LUN. | C14: 44081 | D14: 44109 | E14: 44137 | F14: 44172 | G14: 44200 | H14: 44235 | I14: 44263 | J14: 44291 | K14: 44319 | L14: 44354 | M14: 44382 | N14: 44410 | R14: =IFERROR(RANK(S14,cálculos!$S$5:$S$24,1)+SUMPRODUCT(--(S14=cálculos!$S$5:$S$24),--(U14>cálculos!$U$5:$U$24)),"") | S14: =IFERROR(RANK($T14,cálculos!$T$5:$T$24,1),"") | T14: {=IFERROR(INDEX(AppointmentDetails[],SMALL(IF(AppointmentDetails[FECHA]=TodaysDate,ROW(AppointmentDetails[FECHA])-4),ROW(A10)),2),"")} | U14: {=IFERROR(INDEX(AppointmentDetails[],SMALL(IF(AppointmentDetails[FECHA]=TodaysDate,ROW(AppointmentDetails[FECHA])-4),ROW(A10)),3),"")} | W14: 10 | X14: =IFERROR(VLOOKUP(W14,SortTable[],3,FALSE),"") | Y14: =IFERROR(VLOOKUP(W14,SortTable[],4,FALSE),"")
B15: MAR | C15: 44082 | D15: 44110 | E15: 44138 | F15: 44173 | G15: 44201 | H15: 44236 | I15: 44264 | J15: 44292 | K15: 44320 | L15: 44355 | M15: 44383 | N15: 44411 | R15: =IFERROR(RANK(S15,cálculos!$S$5:$S$24,1)+SUMPRODUCT(--(S15=cálculos!$S$5:$S$24),--(U15>cálculos!$U$5:$U$24)),"") | S15: =IFERROR(RANK($T15,cálculos!$T$5:$T$24,1),"") | T15: {=IFERROR(INDEX(AppointmentDetails[],SMALL(IF(AppointmentDetails[FECHA]=TodaysDate,ROW(AppointmentDetails[FECHA])-4),ROW(A11)),2),"")} | U15: {=IFERROR(INDEX(AppointmentDetails[],SMALL(IF(AppointmentDetails[FECHA]=TodaysDate,ROW(AppointmentDetails[FECHA])-4),ROW(A11)),3),"")} | W15: 11 | X15: =IFERROR(VLOOKUP(W15,SortTable[],3,FALSE),"") | Y15: =IFERROR(VLOOKUP(W15,SortTable[],4,FALSE),"")
B16: MIÉ | C16: 44083 | D16: 44111 | E16: 44139 | F16: 44174 | G16: 44202 | H16: 44237 | I16: 44265 | J16: 44293 | K16: 44321 | L16: 44356 | M16: 44384 | N16: 44412 | R16: =IFERROR(RANK(S16,cálculos!$S$5:$S$24,1)+SUMPRODUCT(--(S16=cálculos!$S$5:$S$24),--(U16>cálculos!$U$5:$U$24)),"") | S16: =IFERROR(RANK($T16,cálculos!$T$5:$T$24,1),"") | T16: {=IFERROR(INDEX(AppointmentDetails[],SMALL(IF(AppointmentDetails[FECHA]=TodaysDate,ROW(AppointmentDetails[FECHA])-4),ROW(A12)),2),"")} | U16: {=IFERROR(INDEX(AppointmentDetails[],SMALL(IF(AppointmentDetails[FECHA]=TodaysDate,ROW(AppointmentDetails[FECHA])-4),ROW(A12)),3),"")} | W16: 12 | X16: =IFERROR(VLOOKUP(W16,SortTable[],3,FALSE),"") | Y16: =IFERROR(VLOOKUP(W16,SortTable[],4,FALSE),"")
B17: JUE | C17: 44084 | D17: 44112 | E17: 44140 | F17: 44175 | G17: 44203 | H17: 44238 | I17: 44266 | J17: 44294 | K17: 44322 | L17: 44357 | M17: 44385 | N17: 44413 | R17: =IFERROR(RANK(S17,cálculos!$S$5:$S$24,1)+SUMPRODUCT(--(S17=cálculos!$S$5:$S$24),--(U17>cálculos!$U$5:$U$24)),"") | S17: =IFERROR(RANK($T17,cálculos!$T$5:$T$24,1),"") | T17: {=IFERROR(INDEX(AppointmentDetails[],SMALL(IF(AppointmentDetails[FECHA]=TodaysDate,ROW(AppointmentDetails[FECHA])-4),ROW(A13)),2),"")} | U17: {=IFERROR(INDEX(AppointmentDetails[],SMALL(IF(AppointmentDetails[FECHA]=TodaysDate,ROW(AppointmentDetails[FECHA])-4),ROW(A13)),3),"")} | W17: 13 | X17: =IFERROR(VLOOKUP(W17,SortTable[],3,FALSE),"") | Y17: =IFERROR(VLOOKUP(W17,SortTable[],4,FALSE),"")
B18: VIE | C18: 44085 | D18: 44113 | E18: 44141 | F18: 44176 | G18: 44204 | H18: 44239 | I18: 44267 | J18: 44295 | K18: 44323 | L18: 44358 | M18: 44386 | N18: 44414 | R18: =IFERROR(RANK(S18,cálculos!$S$5:$S$24,1)+SUMPRODUCT(--(S18=cálculos!$S$5:$S$24),--(U18>cálculos!$U$5:$U$24)),"") | S18: =IFERROR(RANK($T18,cálculos!$T$5:$T$24,1),"") | T18: {=IFERROR(INDEX(AppointmentDetails[],SMALL(IF(AppointmentDetails[FECHA]=TodaysDate,ROW(AppointmentDetails[FECHA])-4),ROW(A14)),2),"")} | U18: {=IFERROR(INDEX(AppointmentDetails[],SMALL(IF(AppointmentDetails[FECHA]=TodaysDate,ROW(AppointmentDetails[FECHA])-4),ROW(A14)),3),"")} | W18: 14 | X18: =IFERROR(VLOOKUP(W18,SortTable[],3,FALSE),"") | Y18: =IFERROR(VLOOKUP(W18,SortTable[],4,FALSE),"")
B19: SÁB | C19: 44086 | D19: 44114 | E19: 44142 | F19: 44177 | G19: 44205 | H19: 44240 | I19: 44268 | J19: 44296 | K19: 44324 | L19: 44359 | M19: 44387 | N19: 44415 | R19: =IFERROR(RANK(S19,cálculos!$S$5:$S$24,1)+SUMPRODUCT(--(S19=cálculos!$S$5:$S$24),--(U19>cálculos!$U$5:$U$24)),"") | S19: =IFERROR(RANK($T19,cálculos!$T$5:$T$24,1),"") | T19: {=IFERROR(INDEX(AppointmentDetails[],SMALL(IF(AppointmentDetails[FECHA]=TodaysDate,ROW(AppointmentDetails[FECHA])-4),ROW(A15)),2),"")} | U19: {=IFERROR(INDEX(AppointmentDetails[],SMALL(IF(AppointmentDetails[FECHA]=TodaysDate,ROW(AppointmentDetails[FECHA])-4),ROW(A15)),3),"")} | W19: 15 | X19: =IFERROR(VLOOKUP(W19,SortTable[],3,FALSE),"") | Y19: =IFERROR(VLOOKUP(W19,SortTable[],4,FALSE),"")
B20: DOM | C20: 44087 | D20: 44115 | E20: 44143 | F20: 44178 | G20: 44206 | H20: 44241 | I20: 44269 | J20: 44297 | K20: 44325 | L20: 44360 | M20: 44388 | N20: 44416 | R20: =IFERROR(RANK(S20,cálculos!$S$5:$S$24,1)+SUMPRODUCT(--(S20=cálculos!$S$5:$S$24),--(U20>cálculos!$U$5:$U$24)),"") | S20: =IFERROR(RANK($T20,cálculos!$T$5:$T$24,1),"") | T20: {=IFERROR(INDEX(AppointmentDetails[],SMALL(IF(AppointmentDetails[FECHA]=TodaysDate,ROW(AppointmentDetails[FECHA])-4),ROW(A16)),2),"")} | U20: {=IFERROR(INDEX(AppointmentDetails[],SMALL(IF(AppointmentDetails[FECHA]=TodaysDate,ROW(AppointmentDetails[FECHA])-4),ROW(A16)),3),"")} | W20: 16 | X20: =IFERROR(VLOOKUP(W20,SortTable[],3,FALSE),"") | Y20: =IFERROR(VLOOKUP(W20,SortTable[],4,FALSE),"")
B21: LUN. | C21: 44088 | D21: 44116 | E21: 44144 | F21: 44179 | G21: 44207 | H21: 44242 | I21: 44270 | J21: 44298 | K21: 44326 | L21: 44361 | M21: 44389 | N21: 44417 | R21: =IFERROR(RANK(S21,cálculos!$S$5:$S$24,1)+SUMPRODUCT(--(S21=cálculos!$S$5:$S$24),--(U21>cálculos!$U$5:$U$24)),"") | S21: =IFERROR(RANK($T21,cálculos!$T$5:$T$24,1),"") | T21: {=IFERROR(INDEX(AppointmentDetails[],SMALL(IF(AppointmentDetails[FECHA]=TodaysDate,ROW(AppointmentDetails[FECHA])-4),ROW(A17)),2),"")} | U21: {=IFERROR(INDEX(AppointmentDetails[],SMALL(IF(AppointmentDetails[FECHA]=TodaysDate,ROW(AppointmentDetails[FECHA])-4),ROW(A17)),3),"")} | W21: 17 | X21: =IFERROR(VLOOKUP(W21,SortTable[],3,FALSE),"") | Y21: =IFERROR(VLOOKUP(W21,SortTable[],4,FALSE),"")
B22: MAR | C22: 44089 | D22: 44117 | E22: 44145 | F22: 44180 | G22: 44208 | H22: 44243 | I22: 44271 | J22: 44299 | K22: 44327 | L22: 44362 | M22: 44390 | N22: 44418 | R22: =IFERROR(RANK(S22,cálculos!$S$5:$S$24,1)+SUMPRODUCT(--(S22=cálculos!$S$5:$S$24),--(U22>cálculos!$U$5:$U$24)),"") | S22: =IFERROR(RANK($T22,cálculos!$T$5:$T$24,1),"") | T22: {=IFERROR(INDEX(AppointmentDetails[],SMALL(IF(AppointmentDetails[FECHA]=TodaysDate,ROW(AppointmentDetails[FECHA])-4),ROW(A18)),2),"")} | U22: {=IFERROR(INDEX(AppointmentDetails[],SMALL(IF(AppointmentDetails[FECHA]=TodaysDate,ROW(AppointmentDetails[FECHA])-4),ROW(A18)),3),"")} | W22: 18 | X22: =IFERROR(VLOOKUP(W22,SortTable[],3,FALSE),"") | Y22: =IFERROR(VLOOKUP(W22,SortTable[],4,FALSE),"")
B23: MIÉ | C23: 44090 | D23: 44118 | E23: 44146 | F23: 44181 | G23: 44209 | H23: 44244 | I23: 44272 | J23: 44300 | K23: 44328 | L23: 44363 | M23: 44391 | N23: 44419 | R23: =IFERROR(RANK(S23,cálculos!$S$5:$S$24,1)+SUMPRODUCT(--(S23=cálculos!$S$5:$S$24),--(U23>cálculos!$U$5:$U$24)),"") | S23: =IFERROR(RANK($T23,cálculos!$T$5:$T$24,1),"") | T23: {=IFERROR(INDEX(AppointmentDetails[],SMALL(IF(AppointmentDetails[FECHA]=TodaysDate,ROW(AppointmentDetails[FECHA])-4),ROW(A19)),2),"")} | U23: {=IFERROR(INDEX(AppointmentDetails[],SMALL(IF(AppointmentDetails[FECHA]=TodaysDate,ROW(AppointmentDetails[FECHA])-4),ROW(A19)),3),"")} | W23: 19 | X23: =IFERROR(VLOOKUP(W23,SortTable[],3,FALSE),"") | Y23: =IFERROR(VLOOKUP(W23,SortTable[],4,FALSE),"")
B24: JUE | C24: 44091 | D24: 44119 | E24: 44147 | F24: 44182 | G24: 44210 | H24: 44245 | I24: 44273 | J24: 44301 | K24: 44329 | L24: 44364 | M24: 44392 | N24: 44420 | R24: =IFERROR(RANK(S24,cálculos!$S$5:$S$24,1)+SUMPRODUCT(--(S24=cálculos!$S$5:$S$24),--(U24>cálculos!$U$5:$U$24)),"") | S24: =IFERROR(RANK($T24,cálculos!$T$5:$T$24,1),"") | T24: {=IFERROR(INDEX(AppointmentDetails[],SMALL(IF(AppointmentDetails[FECHA]=TodaysDate,ROW(AppointmentDetails[FECHA])-4),ROW(A20)),2),"")} | U24: {=IFERROR(INDEX(AppointmentDetails[],SMALL(IF(AppointmentDetails[FECHA]=TodaysDate,ROW(AppointmentDetails[FECHA])-4),ROW(A20)),3),"")} | W24: 20 | X24: =IFERROR(VLOOKUP(W24,SortTable[],3,FALSE),"") | Y24: =IFERROR(VLOOKUP(W24,SortTable[],4,FALSE),"")
B25: VIE | C25: 44092 | D25: 44120 | E25: 44148 | F25: 44183 | G25: 44211 | H25: 44246 | I25: 44274 | J25: 44302 | K25: 44330 | L25: 44365 | M25: 44393 | N25: 44421
B26: SÁB | C26: 44093 | D26: 44121 | E26: 44149 | F26: 44184 | G26: 44212 | H26: 44247 | I26: 44275 | J26: 44303 | K26: 44331 | L26: 44366 | M26: 44394 | N26: 44422
B27: DOM | C27: 44094 | D27: 44122 | E27: 44150 | F27: 44185 | G27: 44213 | H27: 44248 | I27: 44276 | J27: 44304 | K27: 44332 | L27: 44367 | M27: 44395 | N27: 44423
B28: LUN. | C28: 44095 | D28: 44123 | E28: 44151 | F28: 44186 | G28: 44214 | H28: 44249 | I28: 44277 | J28: 44305 | K28: 44333 | L28: 44368 | M28: 44396 | N28: 44424
B29: MAR | C29: 44096 | D29: 44124 | E29: 44152 | F29: 44187 | G29: 44215 | H29: 44250 | I29: 44278 | J29: 44306 | K29: 44334 | L29: 44369 | M29: 44397 | N29: 44425
B30: MIÉ | C30: 44097 | D30: 44125 | E30: 44153 | F30: 44188 | G30: 44216 | H30: 44251 | I30: 44279 | J30: 44307 | K30: 44335 | L30: 44370 | M30: 44398 | N30: 44426
B31: JUE | C31: 44098 | D31: 44126 | E31: 44154 | F31: 44189 | G31: 44217 | H31: 44252 | I31: 44280 | J31: 44308 | K31: 44336 | L31: 44371 | M31: 44399 | N31: 44427
B32: VIE | C32: 44099 | D32: 44127 | E32: 44155 | F32: 44190 | G32: 44218 | H32: 44253 | I32: 44281 | J32: 44309 | K32: 44337 | L32: 44372 | M32: 44400 | N32: 44428
B33: SÁB | C33: 44100 | D33: 44128 | E33: 44156 | F33: 44191 | G33: 44219 | H33: 44254 | I33: 44282 | J33: 44310 | K33: 44338 | L33: 44373 | M33: 44401 | N33: 44429
B34: DOM | C34: 44101 | D34: 44129 | E34: 44157 | F34: 44192 | G34: 44220 | H34: 44255 | I34: 44283 | J34: 44311 | K34: 44339 | L34: 44374 | M34: 44402 | N34: 44430
B35: LUN. | C35: 44102 | D35: 44130 | E35: 44158 | F35: 44193 | G35: 44221 | I35: 44284 | J35: 44312 | K35: 44340 | L35: 44375 | M35: 44403 | N35: 44431
B36: MAR | C36: 44103 | D36: 44131 | E36: 44159 | F36: 44194 | G36: 44222 | I36: 44285 | J36: 44313 | K36: 44341 | L36: 44376 | M36: 44404 | N36: 44432
B37: MIÉ | C37: 44104 | D37: 44132 | E37: 44160 | F37: 44195 | G37: 44223 | I37: 44286 | J37: 44314 | K37: 44342 | L37: 44377 | M37: 44405 | N37: 44433
B38: JUE | D38: 44133 | E38: 44161 | F38: 44196 | G38: 44224 | J38: 44315 | K38: 44343 | M38: 44406 | N38: 44434
B39: VIE | D39: 44134 | E39: 44162 | G39: 44225 | J39: 44316 | K39: 44344 | M39: 44407 | N39: 44435
B40: SÁB | D40: 44135 | E40: 44163 | G40: 44226 | K40: 44345 | M40: 44408 | N40: 44436
...
